Workbook

Sheet Grunddaten
A1: Grundaten zur Liquiditätsplanung
G2: Summe
E3: Kredit- | G3: Bank 1 | H3: Bank 2 | I3: Bank 3 | J3: Bank 4 | K3: Bank 5 | L3: Bank 6 | M3: Bank 7 | N3: Bank 8 | O3: gesamtes
E4: limit | O4: Kreditlimit
D5: Konto-Nr. | E5: T€ | G5: T€ | H5: T€ | I5: T€ | J5: T€ | K5: T€ | L5: T€ | M5: T€ | N5: T€ | O5: T€
A6: Standort 1
A8: 1. | B8: Bank 1 | E8: 550 | G8: =+E8 -> 550 | O8: =SUM(G8:N8) -> 550
A9: 2. | B9: Bank 2 | H9: =+E9 -> 0 | O9: =SUM(G9:N9) -> 0
A10: 3. | B10: Bank 3 | E10: 340.9 | I10: =+E10 -> 340.9 | O10: =SUM(G10:N10) -> 340.9
A11: 4. | B11: Bank 4 | E11: 227.3 | J11: =+E11 -> 227.3 | O11: =SUM(G11:N11) -> 227.3
A12: 5. | B12: Bank 5 | E12: 97.1 | K12: =+E12 -> 97.1 | O12: =SUM(G12:N12) -> 97.1
A13: 6. | B13: Bank 6 | L13: 0 | O13: =SUM(G13:N13) -> 0
A14: 7. | B14: Bank 7 | E14: 25.6 | M14: 25.6 | O14: =SUM(G14:N14) -> 25.6
A15: 8. | B15: Bank 8 | N15: 0 | O15: =SUM(G15:N15) -> 0
E16: =SUM(E8:E15) -> 1240.9 | G16: =SUM(G8:G15) -> 550 | H16: =SUM(H8:H15) -> 0 | I16: =SUM(I8:I15) -> 340.9 | J16: =SUM(J8:J15) -> 227.3 | K16: =SUM(K8:K15) -> 97.1 | L16: =SUM(L8:L15) -> 0 | M16: =SUM(M8:M15) -> 25.6 | N16: =SUM(N8:N15) -> 0 | O16: =SUM(O8:O15) -> 1240.9
A18: Standort 2
A20: 1. | B20: Bank 1 | E20: 0 | G20: =+E20 -> 0 | O20: =SUM(G20:N20) -> 0
A21: 2. | B21: Bank 2 | E21: 481.8 | H21: =+E21 -> 481.8 | O21: =SUM(G21:N21) -> 481.8
A22: 3. | B22: Bank 3 | I22: =+E22 -> 0 | O22: =SUM(G22:N22) -> 0
A23: 4. | B23: Bank 4 | J23: =+E23 -> 0 | O23: =SUM(G23:N23) -> 0
A24: 5. | B24: Bank 5 | E24: 0 | K24: =+E24 -> 0 | O24: =SUM(G24:N24) -> 0
A25: 6. | B25: Bank 6 | L25: 0 | O25: =SUM(G25:N25) -> 0
A26: 7. | B26: Bank 7 | M26: 0 | O26: =SUM(G26:N26) -> 0
A27: 8. | B27: Bank 8 | N27: 0 | O27: =SUM(G27:N27) -> 0
E28: =SUM(E20:E25) -> 481.8 | G28: =SUM(G20:G25) -> 0 | H28: =SUM(H20:H25) -> 481.8 | I28: =SUM(I20:I25) -> 0 | J28: =SUM(J20:J25) -> 0 | K28: =SUM(K20:K25) -> 0 | L28: =SUM(L20:L25) -> 0 | M28: =SUM(M20:M25) -> 0 | N28: =SUM(N20:N25) -> 0 | O28: =SUM(O20:O25) -> 481.8
A30: Standort 3
A32: 1. | B32: Bank 1 | E32: 50 | G32: =+E32 -> 50 | O32: =SUM(G32:N32) -> 50
A33: 2. | B33: Bank 2 | E33: 200 | H33: =+E33 -> 200 | O33: =SUM(G33:N33) -> 200
A34: 3. | B34: Bank 3 | I34: =+E34 -> 0 | O34: =SUM(G34:N34) -> 0
A35: 4. | B35: Bank 4 | J35: =+E35 -> 0 | O35: =SUM(G35:N35) -> 0
A36: 5. | B36: Bank 5 | E36: 0 | K36: =+E36 -> 0 | O36: =SUM(G36:N36) -> 0
A37: 6. | B37: Bank 6 | E37: 50 | L37: 50 | O37: =SUM(G37:N37) -> 50
A38: 7. | B38: Bank 7 | E38: 0 | M38: 0 | O38: =SUM(G38:N38) -> 0
A39: 8. | B39: Bank 8 | N39: 0 | O39: =SUM(G39:N39) -> 0
E40: =SUM(E32:E37) -> 300 | G40: =SUM(G32:G37) -> 50 | H40: =SUM(H32:H37) -> 200 | I40: =SUM(I32:I37) -> 0 | J40: =SUM(J32:J37) -> 0 | K40: =SUM(K32:K37) -> 0 | L40: =SUM(L32:L37) -> 50 | M40: =SUM(M32:M37) -> 0 | N40: =SUM(N32:N37) -> 0 | O40: =SUM(O32:O37) -> 300
A42: Standort 4
A44: 1. | B44: Bank 1 | E44: 500 | G44: =+E44 -> 500 | O44: =SUM(G44:N44) -> 500
A45: 2. | B45: Bank 2 | H45: =+E45 -> 0 | O45: =SUM(G45:N45) -> 0
A46: 3. | B46: Bank 3 | I46: =+E46 -> 0 | O46: =SUM(G46:N46) -> 0
A47: 4. | B47: Bank 4 | J47: =+E47 -> 0 | O47: =SUM(G47:N47) -> 0
...

Sheet Standort 1
A1: Standort 1 | I1: geplant
J2: Name | K2: Datum
A3: Liquiditätsplanung aufgrund der Einzelkonten
A4: Planung in T€
E5: =+Holding!E5 -> Montag | F5: =+Holding!F5 -> Dienstag | G5: =+Holding!G5 -> Mittwoch | H5: =+Holding!H5 -> Donnerstag | I5: =+Holding!I5 -> Freitag | J5: =+Holding!J5 -> Samstag | K5: =+Holding!K5 -> Sonntag | L5: =+Holding!L5 -> Montag
E6: 45870 | F6: =+E6+1 -> 45871 | G6: =+F6+1 -> 45872 | H6: =+G6+1 -> 45873 | I6: =+H6+1 -> 45874 | J6: =+I6+1 -> 45875 | K6: =+J6+1 -> 45876 | L6: =+K6+1 -> 45877
D7: Text | E7: T€ | F7: T€ | G7: T€ | H7: T€ | I7: T€ | J7: T€ | K7: T€ | L7: T€
A8: Bank 1 | E8: Konto-Nr.
D10: Saldo zum Tagesbeginn | E10: -649.5 | F10: =+E41 -> -708.93 | G10: =+F41 -> -652.6 | H10: =+G41 -> -592.6 | I10: =+H41 -> -570.793 | J10: =+I41 -> -565.977 | K10: =+J41 -> -565.977 | L10: =+K41 -> -565.977
A11: Einnahmen
B12: Debitoren | E12: =50+6.5+26+12.089 -> 94.589 | F12: =30+15.2+17.13 -> 62.33 | G12: =15+15 -> 30 | H12: =20+1.349+0.458 -> 21.807 | I12: =20+17.9 -> 37.9 | L12: 20
B13: Verbund
B14: Hersteller Bank 1
B15: Schecks
B16: Hersteller Bank 2
B21: Geldverkehr | G21: 80
D22: Summe Einnahmen | E22: =SUM(E11:E21) -> 94.589 | F22: =SUM(F11:F21) -> 62.33 | G22: =SUM(G11:G21) -> 110 | H22: =SUM(H11:H21) -> 21.807 | I22: =SUM(I11:I21) -> 37.9 | J22: =SUM(J11:J21) -> 0 | K22: =SUM(K11:K21) -> 0 | L22: =SUM(L11:L21) -> 20
A23: Ausgaben
B24: Lohn/Gehalt
B25: Lohnsteuer | E25: =37.619-3.6 -> 34.019
B26: Sozialversicherung | I26: 13.084
B27: Mieten
B28: Ablösung Fzge
B29: Hersteller Bank 1
B30: Kreditoren
B31: Zinsen
B32: Schecks
B36: Geldtransit | E36: 120 | F36: 6 | G36: 50 | I36: 20 | L36: 40
B37: Umsatzsteuer
B38: Geldverkehr
D39: Summe Ausgaben | E39: =SUM(E24:E38) -> 154.019 | F39: =SUM(F24:F38) -> 6 | G39: =SUM(G24:G38) -> 50 | H39: =SUM(H24:H38) -> 0 | I39: =SUM(I24:I38) -> 33.084 | J39: =SUM(J24:J38) -> 0 | K39: =SUM(K24:K38) -> 0 | L39: =SUM(L24:L38) -> 40
D40: Saldo Einnahmen ./. Ausgaben | E40: =+E22-E39 -> -59.43 | F40: =+F22-F39 -> 56.33 | G40: =+G22-G39 -> 60 | H40: =+H22-H39 -> 21.807 | I40: =+I22-I39 -> 4.816 | J40: =+J22-J39 -> 0 | K40: =+K22-K39 -> 0 | L40: =+L22-L39 -> -20
D41: Tagesendsaldo | E41: =+E10+E40 -> -708.93 | F41: =+F10+F40 -> -652.6 | G41: =+G10+G40 -> -592.6 | H41: =+H10+H40 -> -570.793 | I41: =+I10+I40 -> -565.977 | J41: =+J10+J40 -> -565.977 | K41: =+K10+K40 -> -565.977 | L41: =+L10+L40 -> -585.977
A43: Bank 2 | E43: Konto-Nr. | F43: 0
D45: Saldo zum Tagesbeginn | F45: =E75 -> 0 | G45: =F75 -> 0 | H45: =G75 -> 0 | I45: =H75 -> 0 | J45: =I75 -> 0 | K45: =J75 -> 0 | L45: =K75 -> 0
A46: Einnahmen
B55: Geldverkehr
D56: Summe Einnahmen | E56: =SUM(E46:E55) -> 0 | F56: =SUM(F46:F55) -> 0 | G56: =SUM(G46:G55) -> 0 | H56: =SUM(H46:H55) -> 0 | I56: =SUM(I46:I55) -> 0 | J56: =SUM(J46:J55) -> 0 | K56: =SUM(K46:K55) -> 0 | L56: =SUM(L46:L55) -> 0
A57: Ausgaben
B72: Geldverkehr
...

Sheet Standort 2
A1: Standort 2 | I1: geplant | K1: 38971
J2: Name
A3: Liquiditätsplanung aufgrund der Einzelkonten
A4: Planung in T€
E5: =+Holding!E5 -> Montag | F5: =+Holding!F5 -> Dienstag | G5: =+Holding!G5 -> Mittwoch | H5: =+Holding!H5 -> Donnerstag | I5: =+Holding!I5 -> Freitag | J5: =+Holding!J5 -> Samstag | K5: =+Holding!K5 -> Sonntag | L5: =+Holding!L5 -> Montag
E6: 45870 | F6: =+E6+1 -> 45871 | G6: =+F6+1 -> 45872 | H6: =+G6+1 -> 45873 | I6: =+H6+1 -> 45874 | J6: =+I6+1 -> 45875 | K6: =+J6+1 -> 45876 | L6: =+K6+1 -> 45877
D7: Text | E7: T€ | F7: T€ | G7: T€ | H7: T€ | I7: T€ | J7: T€ | K7: T€ | L7: T€
A8: =+Grunddaten!B20 -> Bank 1 | E8: Konto-Nr. | F8: =+Grunddaten!D20 -> 0
D10: Saldo zum Tagesbeginn | E10: 140 | F10: =+E41 -> 108.6 | G10: =+F41 -> 53.3 | H10: =+G41 -> 53.3 | I10: =+H41 -> 53.3 | J10: =+I41 -> 25.3 | K10: =+J41 -> 25.3 | L10: =+K41 -> 25.3
A11: Einnahmen
D12: Debitoren
D14: Scheck retuer
B20: Geldverkehr
D21: Summe Einnahmen | E21: =SUM(E11:E20) -> 0 | F21: =SUM(F11:F20) -> 0 | G21: =SUM(G11:G20) -> 0 | H21: =SUM(H11:H20) -> 0 | I21: =SUM(I11:I20) -> 0 | J21: =SUM(J11:J20) -> 0 | K21: =SUM(K11:K20) -> 0 | L21: =SUM(L11:L20) -> 0
A22: Ausgaben
D23: Leasingauslauf | E23: 1.5
D24: GW-Ankauf
D25: Diverse
D26: Stundung
D27: Verbundene
D28: kreditoren | I28: 28
D29: Ablöse FB
D30: Ablöse FB EF temp. | E30: 29.9 | F30: =18.8+8.6+27.9 -> 55.3
B38: Geldverkehr
D39: Summe Ausgaben | E39: =SUM(E23:E38) -> 31.4 | F39: =SUM(F23:F38) -> 55.3 | G39: =SUM(G23:G38) -> 0 | H39: =SUM(H23:H38) -> 0 | I39: =SUM(I23:I38) -> 28 | J39: =SUM(J23:J38) -> 0 | K39: =SUM(K23:K38) -> 0 | L39: =SUM(L23:L38) -> 0
D40: Saldo Einnahmen ./. Ausgaben | E40: =+E21-E39 -> -31.4 | F40: =+F21-F39 -> -55.3 | G40: =+G21-G39 -> 0 | H40: =+H21-H39 -> 0 | I40: =+I21-I39 -> -28 | J40: =+J21-J39 -> 0 | K40: =+K21-K39 -> 0 | L40: =+L21-L39 -> 0
D41: Tagesendsaldo | E41: =+E10+E40 -> 108.6 | F41: =+F10+F40 -> 53.3 | G41: =+G10+G40 -> 53.3 | H41: =+H10+H40 -> 53.3 | I41: =+I10+I40 -> 25.3 | J41: =+J10+J40 -> 25.3 | K41: =+K10+K40 -> 25.3 | L41: =+L10+L40 -> 25.3
A43: =+Grunddaten!B21 -> Bank 2 | E43: Konto-Nr. | F43: =+Grunddaten!D21 -> 0
D45: Saldo zum Tagesbeginn | E45: -205.8 | F45: =E75 -> -302.5 | G45: =F75 -> -346 | H45: =G75 -> -419.1 | I45: =H75 -> -430.7 | J45: =I75 -> -431.6 | K45: =J75 -> -431.6 | L45: =K75 -> -431.6
A46: Einnahmen
D47: Debitoren | E47: 10 | F47: 10 | G47: 10 | H47: 10 | I47: 10
D48: Kasse | E48: 20.6
D49: geplante AL Kasse | F49: 8 | G49: 16.7
D50: Debitoren Verbund
D52: Auslieferung Überw.
B55: Geldverkehr
D56: Summe Einnahmen | E56: =SUM(E46:E55) -> 30.6 | F56: =SUM(F46:F55) -> 18 | G56: =SUM(G46:G55) -> 26.7 | H56: =SUM(H46:H55) -> 10 | I56: =SUM(I46:I55) -> 10 | J56: =SUM(J46:J55) -> 0 | K56: =SUM(K46:K55) -> 0 | L56: =SUM(L46:L55) -> 0
A57: Ausgaben
D58: GW-Ankauf | E58: 11.2
D59: Diverse | I59: 10.9
...

Sheet Standort 3
A1: Standort 3 | I1: geplant
J2: Name | K2: Datum
A3: Liquiditätsplanung aufgrund der Einzelkonten
A4: Planung in T€
E5: =+Holding!E5 -> Montag | F5: =+Holding!F5 -> Dienstag | G5: =+Holding!G5 -> Mittwoch | H5: =+Holding!H5 -> Donnerstag | I5: =+Holding!I5 -> Freitag | J5: =+Holding!J5 -> Samstag | K5: =+Holding!K5 -> Sonntag | L5: =+Holding!L5 -> Montag
E6: 45870 | F6: =+E6+1 -> 45871 | G6: =+F6+1 -> 45872 | H6: =+G6+1 -> 45873 | I6: =+H6+1 -> 45874 | J6: =+I6+1 -> 45875 | K6: =+J6+1 -> 45876 | L6: =+K6+1 -> 45877
D7: Text | E7: T€ | F7: T€ | G7: T€ | H7: T€ | I7: T€ | J7: T€ | K7: T€ | L7: T€
A8: =+Grunddaten!B32 -> Bank 1 | E8: Konto-Nr. | F8: =+Grunddaten!D32 -> 0
D10: Saldo zum Tagesbeginn | E10: 72.9 | F10: =+E41 -> 72.9 | G10: =+F41 -> 75.9 | H10: =+G41 -> 78.9 | I10: =+H41 -> 81.9 | J10: =+I41 -> 84.9 | K10: =+J41 -> 84.9 | L10: =+K41 -> 84.9
A11: Einnahmen
B12: Debitoren | F12: 3 | G12: 3 | H12: 3 | I12: 3 | L12: 3
B13: Kasse
B21: Geldverkehr
D22: Summe Einnahmen | E22: =SUM(E11:E21) -> 0 | F22: =SUM(F11:F21) -> 3 | G22: =SUM(G11:G21) -> 3 | H22: =SUM(H11:H21) -> 3 | I22: =SUM(I11:I21) -> 3 | J22: =SUM(J11:J21) -> 0 | K22: =SUM(K11:K21) -> 0 | L22: =SUM(L11:L21) -> 3
A23: Ausgaben
B24: Lohn/Gehalt
B25: Lohnsteuer
B26: Sozialversicherung
B27: Mieten
B28: Ablösung Fahrzeuge
B29: Zahlung Kreditoren Verb.
B30: Zahlung Leasingablös.
B31: Zahlung Vergleich
B32: Umbuchung
B33: Zinsen
B38: Geldverkehr
D39: Summe Ausgaben | E39: =SUM(E24:E38) -> 0 | F39: =SUM(F24:F38) -> 0 | G39: =SUM(G24:G38) -> 0 | H39: =SUM(H24:H38) -> 0 | I39: =SUM(I24:I38) -> 0 | J39: =SUM(J24:J38) -> 0 | K39: =SUM(K24:K38) -> 0 | L39: =SUM(L24:L38) -> 0
D40: Saldo Einnahmen ./. Ausgaben | E40: =+E22-E39 -> 0 | F40: =+F22-F39 -> 3 | G40: =+G22-G39 -> 3 | H40: =+H22-H39 -> 3 | I40: =+I22-I39 -> 3 | J40: =+J22-J39 -> 0 | K40: =+K22-K39 -> 0 | L40: =+L22-L39 -> 3
D41: Tagesendsaldo | E41: =+E10+E40 -> 72.9 | F41: =+F10+F40 -> 75.9 | G41: =+G10+G40 -> 78.9 | H41: =+H10+H40 -> 81.9 | I41: =+I10+I40 -> 84.9 | J41: =+J10+J40 -> 84.9 | K41: =+K10+K40 -> 84.9 | L41: =+L10+L40 -> 87.9
A43: =+Grunddaten!B33 -> Bank 2 | E43: Konto-Nr. | F43: =+Grunddaten!D33 -> 0
D45: Saldo zum Tagesbeginn | E45: -104.1 | F45: =E75 -> -183.1 | G45: =F75 -> -193.1 | H45: =G75 -> -198.1 | I45: =H75 -> -192.8 | J45: =I75 -> -202.8 | K45: =J75 -> -202.8 | L45: =K75 -> -202.8
A46: Einnahmen
B47: Debitoren | F47: 20 | G47: 15 | H47: 20 | I47: 20 | L47: 20
B48: Kasse | E48: 9.4
B50: Umsatzsteuer
B55: Geldverkehr
D56: Summe Einnahmen | E56: =SUM(E46:E55) -> 9.4 | F56: =SUM(F46:F55) -> 20 | G56: =SUM(G46:G55) -> 15 | H56: =SUM(H46:H55) -> 20 | I56: =SUM(I46:I55) -> 20 | J56: =SUM(J46:J55) -> 0 | K56: =SUM(K46:K55) -> 0 | L56: =SUM(L46:L55) -> 20
A57: Ausgaben
B58: Loh/Gehalt
B59: Lohnsteuer | E59: 21.8
...

Sheet Standort 4
A1: Standort 4 | I1: geplant
J2: Name | K2: Datum
A3: Liquiditätsplanung aufgrund der Einzelkonten
A4: Planung in T€
E5: =+Holding!E5 -> Montag | F5: =+Holding!F5 -> Dienstag | G5: =+Holding!G5 -> Mittwoch | H5: =+Holding!H5 -> Donnerstag | I5: =+Holding!I5 -> Freitag | J5: =+Holding!J5 -> Samstag | K5: =+Holding!K5 -> Sonntag | L5: =+Holding!L5 -> Montag
E6: 45870 | F6: =+E6+1 -> 45871 | G6: =+F6+1 -> 45872 | H6: =+G6+1 -> 45873 | I6: =+H6+1 -> 45874 | J6: =+I6+1 -> 45875 | K6: =+J6+1 -> 45876 | L6: =+K6+1 -> 45877
D7: Text | E7: T€ | F7: T€ | G7: T€ | H7: T€ | I7: T€ | J7: T€ | K7: T€ | L7: T€
A8: =+Grunddaten!B44 -> Bank 1 | E8: Konto-Nr. | F8: =+Grunddaten!D44 -> 0
D10: Saldo zum Tagesbeginn | E10: -499.2 | F10: =+E41 -> -519.2 | G10: =+F41 -> -535.9 | H10: =+G41 -> -531.4 | I10: =+H41 -> -536.8 | J10: =+I41 -> -540.8 | K10: =+J41 -> -540.8 | L10: =+K41 -> -540.8
A11: Einnahmen
B13: Debitoren | E13: 4.5 | F13: 4.5 | G13: 4.5 | H13: 4.5 | I13: 4.5 | L13: 4.5
B14: Kassen | F14: 3 | L14: 10.5
B15: GW Finanzierungen
B16: Volvo Autobank
B21: Geldverkehr
D22: Summe Einnahmen | E22: =SUM(E11:E21) -> 4.5 | F22: =SUM(F11:F21) -> 7.5 | G22: =SUM(G11:G21) -> 4.5 | H22: =SUM(H11:H21) -> 4.5 | I22: =SUM(I11:I21) -> 4.5 | J22: =SUM(J11:J21) -> 0 | K22: =SUM(K11:K21) -> 0 | L22: =SUM(L11:L21) -> 15
A23: Ausgaben
B24: Löhne/Gehälter
B25: Lohnsteuer | E25: 3.1
B26: Sozialversicherung | E26: 2.4
B27: Kreditoren | H27: 5
B28: Abbuchung Teile Rg. Volvo | F28: 4.7 | I28: 5.3
B29: Tilgung Fahrzeugfinanzierungen | E29: 6.7 | F29: 17.8 | H29: 4.9 | I29: 3.2 | L29: 9.4
B30: Löhne/Gehälter
B31: Ablösung Fahrzeuge | E31: 12.3 | F31: 1.7
B32: Miete
B33: UST
B34: Zinsen Volvo Autobank
B38: Geldverkehr
D39: Summe Ausgaben | E39: =SUM(E24:E38) -> 24.5 | F39: =SUM(F24:F38) -> 24.2 | G39: =SUM(G24:G38) -> 0 | H39: =SUM(H24:H38) -> 9.9 | I39: =SUM(I24:I38) -> 8.5 | J39: =SUM(J24:J38) -> 0 | K39: =SUM(K24:K38) -> 0 | L39: =SUM(L24:L38) -> 9.4
D40: Saldo Einnahmen ./. Ausgaben | E40: =+E22-E39 -> -20 | F40: =+F22-F39 -> -16.7 | G40: =+G22-G39 -> 4.5 | H40: =+H22-H39 -> -5.4 | I40: =+I22-I39 -> -4 | J40: =+J22-J39 -> 0 | K40: =+K22-K39 -> 0 | L40: =+L22-L39 -> 5.6
D41: Tagesendsaldo | E41: =+E10+E40 -> -519.2 | F41: =+F10+F40 -> -535.9 | G41: =+G10+G40 -> -531.4 | H41: =+H10+H40 -> -536.8 | I41: =+I10+I40 -> -540.8 | J41: =+J10+J40 -> -540.8 | K41: =+K10+K40 -> -540.8 | L41: =+L10+L40 -> -535.2
A43: =+Grunddaten!B45 -> Bank 2 | E43: Konto-Nr. | F43: =+Grunddaten!D45 -> 0
D45: Saldo zum Tagesbeginn | F45: =E75 -> 0 | G45: =F75 -> 0 | H45: =G75 -> 0 | I45: =H75 -> 0 | J45: =I75 -> 0 | K45: =J75 -> 0 | L45: =K75 -> 0
A46: Einnahmen
B55: Geldverkehr
D56: Summe Einnahmen | E56: =SUM(E46:E55) -> 0 | F56: =SUM(F46:F55) -> 0 | G56: =SUM(G46:G55) -> 0 | H56: =SUM(H46:H55) -> 0 | I56: =SUM(I46:I55) -> 0 | J56: =SUM(J46:J55) -> 0 | K56: =SUM(K46:K55) -> 0 | L56: =SUM(L46:L55) -> 0
A57: Ausgaben
B72: Geldverkehr
D73: Summe Ausgaben | E73: =SUM(E58:E72) -> 0 | F73: =SUM(F58:F72) -> 0 | G73: =SUM(G58:G72) -> 0 | H73: =SUM(H58:H72) -> 0 | I73: =SUM(I58:I72) -> 0 | J73: =SUM(J58:J72) -> 0 | K73: =SUM(K58:K72) -> 0 | L73: =SUM(L58:L72) -> 0
...

Sheet Holding
A1: Holding | I1: geplant
J2: Name | K2: Datum
A3: Liquiditätsplanung aufgrund der Einzelkonten
A4: Planung in T€
E5: Montag | F5: Dienstag | G5: Mittwoch | H5: Donnerstag | I5: Freitag | J5: Samstag | K5: Sonntag | L5: Montag
E6: 45870 | F6: =+E6+1 -> 45871 | G6: =+F6+1 -> 45872 | H6: =+G6+1 -> 45873 | I6: =+H6+1 -> 45874 | J6: =+I6+1 -> 45875 | K6: =+J6+1 -> 45876 | L6: =+K6+1 -> 45877
D7: Text | E7: T€ | F7: T€ | G7: T€ | H7: T€ | I7: T€ | J7: T€ | K7: T€ | L7: T€
A8: =+Grunddaten!B56 -> Bank 1 | E8: Konto-Nr. | F8: =+Grunddaten!D56 -> 0
D10: Saldo zum Tagesbeginn | E10: -457.9 | F10: =+E41 -> -444.5 | G10: =+F41 -> -444.1 | H10: =+G41 -> -444.1 | I10: =+H41 -> -442.6 | J10: =+I41 -> -439.6 | K10: =+J41 -> -439.6 | L10: =+K41 -> -439.6
A11: Einnahmen
B13: xxxx
B14: verbundene Unternehmen | E14: 3.6 | F14: 0.4 | G14: 2.3 | H14: 2 | I14: 3 | L14: 4.4
B15: xxxx | E15: 9.8
B16: Gew./Kö.St. L
B17: xxxx
B18: xxxx
B21: Geldverkehr
D22: Summe Einnahmen | E22: =SUM(E11:E21) -> 13.4 | F22: =SUM(F11:F21) -> 0.4 | G22: =SUM(G11:G21) -> 2.3 | H22: =SUM(H11:H21) -> 2 | I22: =SUM(I11:I21) -> 3 | J22: =SUM(J11:J21) -> 0 | K22: =SUM(K11:K21) -> 0 | L22: =SUM(L11:L21) -> 4.4
A23: Ausgaben
B25: Zlg. Kreditoren | G25: 2.3 | H25: 0.5
B26: Zlg. Verbundene Unternehmen
B27: Geldverkehr
B28: Office ED | L28: 6.8
B29: xxxxx
B30: xxxx
B31: Zinsen/Tilgung Banken
B32: Grundbesitzabgaben
B33: Sozialversicherung
D39: Summe Ausgaben | E39: =SUM(E24:E38) -> 0 | F39: =SUM(F24:F38) -> 0 | G39: =SUM(G24:G38) -> 2.3 | H39: =SUM(H24:H38) -> 0.5 | I39: =SUM(I24:I38) -> 0 | J39: =SUM(J24:J38) -> 0 | K39: =SUM(K24:K38) -> 0 | L39: =SUM(L24:L38) -> 6.8
D40: Saldo Einnahmen ./. Ausgaben | E40: =+E22-E39 -> 13.4 | F40: =+F22-F39 -> 0.4 | G40: =+G22-G39 -> 0 | H40: =+H22-H39 -> 1.5 | I40: =+I22-I39 -> 3 | J40: =+J22-J39 -> 0 | K40: =+K22-K39 -> 0 | L40: =+L22-L39 -> -2.4
D41: Tagesendsaldo | E41: =+E10+E40 -> -444.5 | F41: =+F10+F40 -> -444.1 | G41: =+G10+G40 -> -444.1 | H41: =+H10+H40 -> -442.6 | I41: =+I10+I40 -> -439.6 | J41: =+J10+J40 -> -439.6 | K41: =+K10+K40 -> -439.6 | L41: =+L10+L40 -> -442
A43: =+Grunddaten!B57 -> Bank 2 | E43: Konto-Nr. | F43: =+Grunddaten!D57 -> 0
D45: Saldo zum Tagesbeginn | F45: =E75 -> 0 | G45: =F75 -> 0 | H45: =G75 -> 0 | I45: =H75 -> 0 | J45: =I75 -> 0 | K45: =J75 -> 0 | L45: =K75 -> 0
A46: Einnahmen
B55: Geldverkehr
D56: Summe Einnahmen | E56: =SUM(E46:E55) -> 0 | F56: =SUM(F46:F55) -> 0 | G56: =SUM(G46:G55) -> 0 | H56: =SUM(H46:H55) -> 0 | I56: =SUM(I46:I55) -> 0 | J56: =SUM(J46:J55) -> 0 | K56: =SUM(K46:K55) -> 0 | L56: =SUM(L46:L55) -> 0
A57: Ausgaben
B72: Geldverkehr
D73: Summe Ausgaben | E73: =SUM(E58:E72) -> 0 | F73: =SUM(F58:F72) -> 0 | G73: =SUM(G58:G72) -> 0 | H73: =SUM(H58:H72) -> 0 | I73: =SUM(I58:I72) -> 0 | J73: =SUM(J58:J72) -> 0 | K73: =SUM(K58:K72) -> 0 | L73: =SUM(L58:L72) -> 0
D74: Saldo Einnahmen ./. Ausgaben | E74: =+E56-E73 -> 0 | F74: =+F56-F73 -> 0 | G74: =+G56-G73 -> 0 | H74: =+H56-H73 -> 0 | I74: =+I56-I73 -> 0 | J74: =+J56-J73 -> 0 | K74: =+K56-K73 -> 0 | L74: =+L56-L73 -> 0
...
